<?xml version="1.0" ?>
<!-- =================================================================================== -->
<!-- |    This document was autogenerated by xacro from /home/lyt/WorkSpace/thbi_robot/tharm_ws/src/er7pro_ag95/er7pro_ag95_description/urdf/er7pro_ag95.urdf.xacro | -->
<!-- |    EDITING THIS FILE BY HAND IS NOT RECOMMENDED                                 | -->
<!-- =================================================================================== -->
<robot name="er7pro_ag95">
    <!-- Constants for robot dimensions -->
    <material name="black">
        <color rgba="0.0 0.0 0.0 1.0" />
    </material>
    <material name="blue">
        <color rgba="0.0 0.0 0.8 1.0" />
    </material>
    <material name="green">
        <color rgba="0.0 0.8 0.0 1.0" />
    </material>
    <material name="grey">
        <color rgba="0.2 0.2 0.2 1.0" />
    </material>
    <material name="orange">
        <color rgba="1.0 0.4235294117647059 0.0392156862745098 1.0" />
    </material>
    <material name="brown">
        <color rgba="0.8705882352941177 0.8117647058823529 0.7647058823529411 1.0" />
    </material>
    <material name="red">
        <color rgba="0.8 0.0 0.0 1.0" />
    </material>
    <material name="white">
        <color rgba="1.0 1.0 1.0 1.0" />
    </material>
    <material name="Beige">
        <color rgba="1.0 0.784 0.5765 1.0" />
    </material>
    <!-- Used for fixing robot to Gazebo 'base_link' -->
    <link name="world" />
    <joint name="fixed" type="fixed">
        <parent link="world" />
        <child link="xMatePro7_base" />
    </joint>
    <!--base-->
    <link name="xMatePro7_base">
        <visual>
            <geometry>
                <mesh filename="package://rokae_description/meshes/xMateER7p/visual/xMatePro7_base.stl" scale="0.001 0.001 0.001" />
            </geometry>
            <origin rpy="0 0 0" xyz="0.0 0.0 0.0" />
            <material name="white" />
        </visual>
        <inertial>
            <mass value="5.48267" />
            <inertia ixx="0.056" ixy="0" ixz="0" iyy="0.066" iyz="0" izz="0.035" />
            <origin rpy="0 0 0" xyz="-0.0183 0 0.067" />
        </inertial>
        <collision>
            <geometry>
                <mesh filename="package://rokae_description/meshes/xMateER7p/collision/xMatePro7_base.stl" scale="0.001 0.001 0.001" />
            </geometry>
            <origin rpy="0 0 0" xyz="0.0 0.0 0.0" />
        </collision>
    </link>
    <joint name="joint1" type="revolute">
        <parent link="xMatePro7_base" />
        <child link="xMatePro7_link1" />
        <limit effort="300" lower="-3.0527" upper="3.0527" velocity="10" />
        <axis xyz="0 0 1" />
        <origin rpy="0 0 0" xyz="0 0 0" />
    </joint>
    <transmission name="tran1">
        <type>transmission_interface/SimpleTransmission</type>
        <joint name="xmate_joint_1">
            <hardwareInterface>EffortJointInterface</hardwareInterface>
        </joint>
        <actuator name="motor1">
            <hardwareInterface>EffortJointInterface</hardwareInterface>
            <mechanicalReduction>1</mechanicalReduction>
        </actuator>
    </transmission>
    <!--link 1-->
    <link name="xMatePro7_link1">
        <visual>
            <geometry>
                <mesh filename="package://rokae_description/meshes/xMateER7p/visual/xMatePro7_link1.stl" scale="0.001 0.001 0.001" />
            </geometry>
            <origin rpy="0 0 0" xyz="0 0 0" />
            <material name="white" />
        </visual>
        <inertial>
            <mass value="5.96204" />
            <inertia ixx="0.051" ixy="0" ixz="0" iyy="0.049" iyz="-0.007" izz="7.176" />
            <origin rpy="0 0 0" xyz="0 -0.017 0.320" />
        </inertial>
        <collision>
            <geometry>
                <mesh filename="package://rokae_description/meshes/xMateER7p/collision/xMatePro7_link1.stl" scale="0.001 0.001 0.001" />
            </geometry>
            <origin rpy="0 0 0" xyz="0 0 0" />
        </collision>
    </link>
    <joint name="joint2" type="revolute">
        <parent link="xMatePro7_link1" />
        <child link="xMatePro7_link2" />
        <limit effort="300" lower="-2.0933" upper="2.0933" velocity="10" />
        <axis xyz="0 1 0" />
        <origin rpy="0 0 0" xyz="0 0 0.404" />
    </joint>
    <transmission name="tran2">
        <type>transmission_interface/SimpleTransmission</type>
        <joint name="xmate_joint_2">
            <hardwareInterface>EffortJointInterface</hardwareInterface>
        </joint>
        <actuator name="motor2">
            <hardwareInterface>EffortJointInterface</hardwareInterface>
            <mechanicalReduction>1</mechanicalReduction>
        </actuator>
    </transmission>
    <!--link 2-->
    <link name="xMatePro7_link2">
        <visual>
            <geometry>
                <mesh filename="package://rokae_description/meshes/xMateER7p/visual/xMatePro7_link2.stl" scale="0.001 0.001 0.001" />
            </geometry>
            <origin rpy="0 0 0" xyz="0 0 0.0" />
            <material name="white" />
        </visual>
        <inertial>
            <mass value="5.40302" />
            <inertia ixx="0.070" ixy="0" ixz="0" iyy="7.230" iyz="-0.014" izz="0.011" />
            <origin rpy="0 0 0" xyz="0 0.032 0.093" />
        </inertial>
        <collision>
            <geometry>
                <mesh filename="package://rokae_description/meshes/xMateER7p/collision/xMatePro7_link2.stl" scale="0.001 0.001 0.001" />
            </geometry>
            <origin rpy="0 0 0" xyz="0 0 0.0" />
        </collision>
    </link>
    <joint name="joint3" type="revolute">
        <parent link="xMatePro7_link2" />
        <child link="xMatePro7_link3" />
        <limit effort="300" lower="-3.0527" upper="3.0527" velocity="10" />
        <axis xyz="0 0 1" />
        <origin rpy="0 0 0" xyz="0 0 0.23743878" />
    </joint>
    <transmission name="tran3">
        <type>transmission_interface/SimpleTransmission</type>
        <joint name="xmate_joint_3">
            <hardwareInterface>EffortJointInterface</hardwareInterface>
        </joint>
        <actuator name="motor3">
            <hardwareInterface>EffortJointInterface</hardwareInterface>
            <mechanicalReduction>1</mechanicalReduction>
        </actuator>
    </transmission>
    <!--${nameofManipulator}_link 3-->
    <link name="xMatePro7_link3">
        <visual>
            <geometry>
                <mesh filename="package://rokae_description/meshes/xMateER7p/visual/xMatePro7_link3.stl" scale="0.001 0.001 0.001" />
            </geometry>
            <origin rpy="0 0 0" xyz="0 0 0.15549959" />
            <material name="white" />
        </visual>
        <inertial>
            <mass value="3.95735" />
            <inertia ixx="0.022" ixy="0" ixz="0" iyy="0.021" iyz="-0.002" izz="1.12" />
            <origin rpy="0 0 0" xyz="0 -0.013 -0.067" />
        </inertial>
        <collision>
            <geometry>
                <mesh filename="package://rokae_description/meshes/xMateER7p/collision/xMatePro7_link3.stl" scale="0.001 0.001 0.001" />
            </geometry>
            <origin rpy="0 0 0" xyz="0 0 0.15549959" />
        </collision>
    </link>
    <joint name="joint4" type="revolute">
        <parent link="xMatePro7_link3" />
        <child link="xMatePro7_link4" />
        <limit effort="300" lower="-2.0933" upper="2.0933" velocity="10" />
        <!--     lower="-2.79" upper="2.79" -->
        <axis xyz="0 1 0" />
        <!--     <origin rpy="0 0 0" xyz="0.585 0.0 0.035"/> -->
        <origin rpy="0 0 0" xyz="0 0 0.15549959" />
    </joint>
    <transmission name="tran4">
        <type>transmission_interface/SimpleTransmission</type>
        <joint name="xmate_joint_4">
            <hardwareInterface>EffortJointInterface</hardwareInterface>
        </joint>
        <actuator name="motor4">
            <hardwareInterface>EffortJointInterface</hardwareInterface>
            <mechanicalReduction>1</mechanicalReduction>
        </actuator>
    </transmission>
    <!--link 4-->
    <link name="xMatePro7_link4">
        <visual>
            <geometry>
                <mesh filename="package://rokae_description/meshes/xMateER7p/visual/xMatePro7_link4.stl" scale=".001 0.001 0.001" />
            </geometry>
            <origin rpy="0 0 0" xyz="0.0 0.0 0.0" />
            <material name="white" />
        </visual>
        <inertial>
            <mass value="2.91217" />
            <inertia ixx="0.024" ixy="0" ixz="0" iyy="1.138" iyz="-0.004" izz="0.005" />
            <origin rpy="0 0 0" xyz="0 0.026 0.068" />
        </inertial>
        <collision>
            <geometry>
                <mesh filename="package://rokae_description/meshes/xMateER7p/collision/xMatePro7_link4.stl" scale="0.001 0.001 0.001" />
            </geometry>
            <origin rpy="0 0 0" xyz="0.0 0.0 0.0" />
        </collision>
    </link>
    <joint name="joint5" type="revolute">
        <parent link="xMatePro7_link4" />
        <child link="xMatePro7_link5" />
        <limit effort="300" lower="-3.0527" upper="3.0527" velocity="10" />
        <axis xyz="0 0 1" />
        <origin rpy="0 0 0" xyz="0 0 0.22044633" />
    </joint>
    <transmission name="tran5">
        <type>transmission_interface/SimpleTransmission</type>
        <joint name="xmate_joint_5">
            <hardwareInterface>EffortJointInterface</hardwareInterface>
        </joint>
        <actuator name="motor5">
            <hardwareInterface>EffortJointInterface</hardwareInterface>
            <mechanicalReduction>1</mechanicalReduction>
        </actuator>
    </transmission>
    <!--link 5-->
    <link name="xMatePro7_link5">
        <visual>
            <geometry>
                <mesh filename="package://rokae_description/meshes/xMateER7p/visual/xMatePro7_link5.stl" scale="0.001 0.001 0.001" />
            </geometry>
            <origin rpy="0 0 0" xyz="0 0 0.14512568" />
            <material name="white" />
        </visual>
        <inertial>
            <mass value="2.47056" />
            <inertia ixx="0.019" ixy="0" ixz="0" iyy="0.018" iyz="-0.002" izz="0.339" />
            <origin rpy="0 0 0" xyz="0 -0.014 -0.079" />
        </inertial>
        <collision>
            <geometry>
                <mesh filename="package://rokae_description/meshes/xMateER7p/collision/xMatePro7_link5.stl" scale="0.001 0.001 0.001" />
            </geometry>
            <origin rpy="0 0 0" xyz="0 0 0.14512568" />
        </collision>
    </link>
    <joint name="joint6" type="revolute">
        <parent link="xMatePro7_link5" />
        <child link="xMatePro7_link6" />
        <limit effort="300" lower="-2.0933" upper="2.0933" velocity="10" />
        <axis xyz="0 1 0" />
        <origin rpy="0.0 0.0 0" xyz="0 0 0.14512568" />
    </joint>
    <transmission name="tran6">
        <type>transmission_interface/SimpleTransmission</type>
        <joint name="xmate_joint_6">
            <hardwareInterface>EffortJointInterface</hardwareInterface>
        </joint>
        <actuator name="motor6">
            <hardwareInterface>EffortJointInterface</hardwareInterface>
            <mechanicalReduction>1</mechanicalReduction>
        </actuator>
    </transmission>
    <!--link 6-->
    <link name="xMatePro7_link6">
        <visual>
            <geometry>
                <mesh filename="package://rokae_description/meshes/xMateER7p/visual/xMatePro7_link6.stl" scale="0.001 0.001 0.001" />
            </geometry>
            <origin rpy="0 0 0" xyz="0.0 0.0 0.0" />
            <material name="white" />
        </visual>
        <inertial>
            <mass value="2.16053" />
            <inertia ixx="0.016" ixy="0" ixz="0" iyy="0.351" iyz="-0.003" izz="0.003" />
            <origin rpy="0 0 0" xyz="0 0.020 0.085" />
        </inertial>
        <collision>
            <geometry>
                <mesh filename="package://rokae_description/meshes/xMateER7p/collision/xMatePro7_link6.stl" scale="0.001 0.001 0.001" />
            </geometry>
            <origin rpy="0 0 0" xyz="0.0 0.0 0.0" />
        </collision>
    </link>
    <joint name="joint7" type="revolute">
        <parent link="xMatePro7_link6" />
        <child link="xMatePro7_link7" />
        <limit effort="300" lower="-6.283" upper="6.283" velocity="10" />
        <axis xyz="0 0 1" />
        <origin rpy="0.0 0.0 0.0" xyz="0 0 0.25090877" />
    </joint>
    <transmission name="tran7">
        <type>transmission_interface/SimpleTransmission</type>
        <joint name="xmate_joint_7">
            <hardwareInterface>EffortJointInterface</hardwareInterface>
        </joint>
        <actuator name="motor7">
            <hardwareInterface>EffortJointInterface</hardwareInterface>
            <mechanicalReduction>1</mechanicalReduction>
        </actuator>
    </transmission>
    <!--link 7-->
    <link name="xMatePro7_link7">
        <visual>
            <geometry>
                <mesh filename="package://rokae_description/meshes/xMateER7p/visual/xMatePro7_link7.stl" scale="0.001 0.001 0.001" />
            </geometry>
            <origin rpy="0 0 0" xyz="0 0 0" />
            <material name="white" />
        </visual>
        <inertial>
            <mass value="1.26834" />
            <inertia ixx="0.002" ixy="-0.000000" ixz="-0.000000" iyy="0.001" iyz="-0.000000" izz="0.337" />
            <origin rpy="0 0 0" xyz="0 0.012 -0.052" />
        </inertial>
        <collision>
            <geometry>
                <mesh filename="package://rokae_description/meshes/xMateER7p/collision/xMatePro7_link7.stl" scale="0.001 0.001 0.001" />
            </geometry>
            <origin rpy="0 0 0" xyz="0 0 0" />
        </collision>
    </link>
    <!-- ros_control plugin 该插件以及在导入机械臂时候加了 所以这里就不用加ros_control插件-->
    <gazebo reference="gripper_base_link">
        <material>Gazebo/Gray</material>
        <plugin name="gazebo_ros_control">
            <robotNamespace>/</robotNamespace>
        </plugin>
    </gazebo>
    <!-- <gazebo reference="finger2_link">
    <material> Gazebo/Gray</material>
  </gazebo> -->
    <!-- 添加末端dummy_gripper 手爪末端 虚拟关节 -->
    <link name="dummy_gripper" />
    <joint name="dummy_joint" type="fixed">
        <origin rpy="0 0 0" xyz="0 0 0.185" />
        <parent link="gripper_base_link" />
        <child link="dummy_gripper" />
    </joint>
    <joint name="gripper_base_joint" type="fixed">
        <parent link="xMatePro7_link7" />
        <child link="gripper_base_link" />
        <origin rpy="0 0 -1.1780972447948965" xyz="0 0 0" />
    </joint>
    <link name="gripper_base_link">
        <visual>
            <geometry>
                <mesh filename="package://dh_ag95_description/meshes/visual/base_link.STL" scale="0.001 0.001 0.001" />
            </geometry>
            <material name="grey">
                <color rgba="0.2 0.2 0.2 1.0" />
            </material>
        </visual>
        <collision>
            <geometry>
                <mesh filename="package://dh_ag95_description/meshes/visual/base_link.STL" scale="0.001 0.001 0.001" />
            </geometry>
        </collision>
        <inertial>
            <mass value="0.83416" />
            <origin xyz="0.0 0.0 0.0" rpy="0 0 0" />
            <inertia ixx="0.0013016" ixy="-6.9374e-07" ixz="5.9848e-07" iyx="0.000000" iyy="0.00049972" iyz="2.0244E-07" izx="0.000000" izy="0.000000" izz="0.001498" />
        </inertial>
    </link>
    <gazebo reference="gripper_base_link">
        <implicitSpringDamper>1</implicitSpringDamper>
        <mu1>100000</mu1>
        <mu2>100000</mu2>
        <kp>100000000.0</kp>
        <kd>1.0</kd>
    </gazebo>
    <joint name="gripper_finger1_joint" type="revolute">
        <parent link="gripper_base_link" />
        <child link="gripper_finger1_knuckle_link" />
        <axis xyz="0 -1 0" />
        <origin rpy="0.0 0.0 3.141592653589793" xyz="-0.016 0 0.10586" />
        <limit effort="1000" lower="0.0" upper="0.65" velocity="2.0" />
    </joint>
    <joint name="gripper_finger2_joint" type="revolute">
        <parent link="gripper_base_link" />
        <child link="gripper_finger2_knuckle_link" />
        <axis xyz="0 -1 0" />
        <origin rpy="0.0 0.0 0.0" xyz="0.016  0 0.10586 " />
        <limit effort="1000" lower="-3.14" upper="3.14" velocity="100.0" />
        <mimic joint="gripper_finger1_joint" />
    </joint>
    <link name="gripper_finger1_knuckle_link">
        <visual>
            <geometry>
                <mesh filename="package://dh_ag95_description/meshes/visual/crank_Link.STL" scale="0.001 0.001 0.001" />
            </geometry>
            <material name="grey">
                <color rgba="0.2 0.2 0.2 1.0" />
            </material>
        </visual>
        <collision>
            <geometry>
                <mesh filename="package://dh_ag95_description/meshes/visual/crank_Link.STL" scale="0.001 0.001 0.001" />
            </geometry>
        </collision>
        <inertial>
            <mass value="0.011111" />
            <origin xyz="0.0 0.0 0.0" rpy="0 0 0" />
            <inertia ixx="3.88172e-06" ixy="-2.29456e-13" ixz="8.33e-07" iyx="0.000000" iyy="1.92174e-06" iyz="2.04435e-13" izx="0.000000" izy="0.000000" izz="4.32374e-06" />
        </inertial>
    </link>
    <gazebo reference="gripper_finger1_knuckle_link">
        <implicitSpringDamper>1</implicitSpringDamper>
        <mu1>100000</mu1>
        <mu2>100000</mu2>
        <kp>100000000.0</kp>
        <kd>1.0</kd>
    </gazebo>
    <link name="gripper_finger2_knuckle_link">
        <visual>
            <geometry>
                <mesh filename="package://dh_ag95_description/meshes/visual/crank_Link.STL" scale="0.001 0.001 0.001" />
            </geometry>
            <material name="grey">
                <color rgba="0.2 0.2 0.2 1.0" />
            </material>
        </visual>
        <collision>
            <geometry>
                <mesh filename="package://dh_ag95_description/meshes/visual/crank_Link.STL" scale="0.001 0.001 0.001" />
            </geometry>
        </collision>
        <inertial>
            <mass value="0.011111" />
            <origin xyz="0.0 0.0 0.0" rpy="0 0 0" />
            <inertia ixx="3.88172e-06" ixy="-2.29456e-13" ixz="8.33e-07" iyx="0.000000" iyy="1.92174e-06" iyz="2.04435e-13" izx="0.000000" izy="0.000000" izz="4.32374e-06" />
        </inertial>
    </link>
    <gazebo reference="gripper_finger2_knuckle_link">
        <implicitSpringDamper>1</implicitSpringDamper>
        <mu1>100000</mu1>
        <mu2>100000</mu2>
        <kp>100000000.0</kp>
        <kd>1.0</kd>
    </gazebo>
    <joint name="gripper_finger1_finger_joint" type="continuous">
        <parent link="gripper_finger1_knuckle_link" />
        <child link="gripper_finger1_finger_link" />
        <axis xyz="0 -1 0" />
        <origin rpy="0 0 0" xyz="0.0292080077784 0.0 -0.0227132622407" />
        <limit effort="0.1" lower="-3.14" upper="3.14" velocity="100.0" />
        <mimic joint="gripper_finger1_joint" multiplier="0.4563942" offset="0" />
    </joint>
    <joint name="gripper_finger2_finger_joint" type="continuous">
        <parent link="gripper_finger2_knuckle_link" />
        <child link="gripper_finger2_finger_link" />
        <axis xyz="0 -1 0" />
        <origin rpy="0 0 0" xyz="0.0292080077784 0.0 -0.0227132622407" />
        <limit effort="0.1" lower="-3.14" upper="3.14" velocity="100.0" />
        <mimic joint="gripper_finger1_joint" multiplier="0.4563942" offset="0" />
    </joint>
    <link name="gripper_finger1_finger_link">
        <visual>
            <geometry>
                <mesh filename="package://dh_ag95_description/meshes/visual/rod_Link.STL" scale="0.001 0.001 0.001" />
            </geometry>
            <material name="grey">
                <color rgba="0.2 0.2 0.2 1.0" />
            </material>
        </visual>
        <collision>
            <geometry>
                <mesh filename="package://dh_ag95_description/meshes/visual/rod_Link.STL" scale="0.001 0.001 0.001" />
            </geometry>
        </collision>
        <inertial>
            <mass value="0.0222871" />
            <origin xyz="0.0 0.0 0.0" rpy="0 0 0" />
            <inertia ixx="8.72836e-06" ixy="7.0843e-15" ixz="-2.18833e-06" iyx="-0.000002" iyy="7.26157e-06" iyz="7.6579e-15" izx="0.000000" izy="0.000000" izz="3.3425e-06" />
        </inertial>
    </link>
    <gazebo reference="gripper_finger1_finger_link">
        <implicitSpringDamper>1</implicitSpringDamper>
        <mu1>100000</mu1>
        <mu2>100000</mu2>
        <kp>100000000.0</kp>
        <kd>1.0</kd>
    </gazebo>
    <link name="gripper_finger2_finger_link">
        <visual>
            <geometry>
                <mesh filename="package://dh_ag95_description/meshes/visual/rod_Link.STL" scale="0.001 0.001 0.001" />
            </geometry>
            <material name="grey">
                <color rgba="0.2 0.2 0.2 1.0" />
            </material>
        </visual>
        <collision>
            <geometry>
                <mesh filename="package://dh_ag95_description/meshes/visual/rod_Link.STL" scale="0.001 0.001 0.001" />
            </geometry>
        </collision>
        <inertial>
            <mass value="0.0222871" />
            <origin xyz="0.0 0.0 0.0" rpy="0 0 0" />
            <inertia ixx="8.72836e-06" ixy="7.0843e-15" ixz="-2.18833e-06" iyx="-0.000002" iyy="7.26157e-06" iyz="7.6579e-15" izx="0.000000" izy="0.000000" izz="3.3425e-06" />
        </inertial>
    </link>
    <gazebo reference="gripper_finger2_finger_link">
        <implicitSpringDamper>1</implicitSpringDamper>
        <mu1>100000</mu1>
        <mu2>100000</mu2>
        <kp>100000000.0</kp>
        <kd>1.0</kd>
    </gazebo>
    <joint name="gripper_finger1_inner_knuckle_joint" type="continuous">
        <parent link="gripper_base_link" />
        <child link="gripper_finger1_inner_knuckle_link" />
        <axis xyz="0 -1 0" />
        <origin rpy="0.0 0.0 3.141592653589793" xyz="-0.016 0 0.10586" />
        <limit effort="0.1" lower="-3.14" upper="3.14" velocity="100.0" />
        <mimic joint="gripper_finger1_joint" multiplier="1.49462955" offset="0" />
    </joint>
    <joint name="gripper_finger2_inner_knuckle_joint" type="continuous">
        <parent link="gripper_base_link" />
        <child link="gripper_finger2_inner_knuckle_link" />
        <axis xyz="0 -1 0" />
        <origin rpy="0.0 0.0 0.0" xyz="0.016 0 0.10586" />
        <limit effort="0.1" lower="-3.14" upper="3.14" velocity="100.0" />
        <mimic joint="gripper_finger1_joint" multiplier="1.49462955" offset="0" />
    </joint>
    <link name="gripper_finger1_inner_knuckle_link">
        <visual>
            <geometry>
                <mesh filename="package://dh_ag95_description/meshes/visual/proximal_phalanx_Link.STL" scale="0.001 0.001 0.001" />
            </geometry>
            <material name="grey">
                <color rgba="0.2 0.2 0.2 1.0" />
            </material>
        </visual>
        <collision>
            <geometry>
                <mesh filename="package://dh_ag95_description/meshes/visual/proximal_phalanx_Link.STL" scale="0.001 0.001 0.001" />
            </geometry>
        </collision>
        <inertial>
            <mass value="0.0318004" />
            <origin xyz="0.0 0.0 0.0" rpy="0 0 0" />
            <inertia ixx="1.39848e-05" ixy="-9.54763e-15" ixz="-5.01422e-06" iyx="0.000000" iyy="1.04943e-05" iyz="8.94585e-16" izx="0.000000" izy="0.000000" izz="1.36183e-05" />
        </inertial>
    </link>
    <gazebo reference="gripper_finger1_inner_knuckle_link">
        <implicitSpringDamper>1</implicitSpringDamper>
        <mu1>100000</mu1>
        <mu2>100000</mu2>
        <kp>100000000.0</kp>
        <kd>1.0</kd>
    </gazebo>
    <link name="gripper_finger2_inner_knuckle_link">
        <visual>
            <geometry>
                <mesh filename="package://dh_ag95_description/meshes/visual/proximal_phalanx_Link.STL" scale="0.001 0.001 0.001" />
            </geometry>
            <material name="grey">
                <color rgba="0.2 0.2 0.2 1.0" />
            </material>
        </visual>
        <collision>
            <geometry>
                <mesh filename="package://dh_ag95_description/meshes/visual/proximal_phalanx_Link.STL" scale="0.001 0.001 0.001" />
            </geometry>
        </collision>
        <inertial>
            <mass value="0.0318004" />
            <origin xyz="0.0 0.0 0.0" rpy="0 0 0" />
            <inertia ixx="1.39848e-05" ixy="-9.54763e-15" ixz="-5.01422e-06" iyx="0.000000" iyy="1.04943e-05" iyz="8.94585e-16" izx="0.000000" izy="0.000000" izz="1.36183e-05" />
        </inertial>
    </link>
    <gazebo reference="gripper_finger2_inner_knuckle_link">
        <implicitSpringDamper>1</implicitSpringDamper>
        <mu1>100000</mu1>
        <mu2>100000</mu2>
        <kp>100000000.0</kp>
        <kd>1.0</kd>
    </gazebo>
    <joint name="gripper_finger1_finger_tip_joint" type="continuous">
        <parent link="gripper_finger1_inner_knuckle_link" />
        <child link="gripper_finger1_finger_tip_link" />
        <axis xyz="0 1 0" />
        <origin rpy="0.0 0.0 0.0" xyz="0.0394969463769 0.0 0.0382752038125 " />
        <limit effort="0.1" lower="-3.14" upper="3.14" velocity="100.0" />
        <mimic joint="gripper_finger1_joint" multiplier="1.49462955" />
    </joint>
    <joint name="gripper_finger2_finger_tip_joint" type="continuous">
        <parent link="gripper_finger2_inner_knuckle_link" />
        <child link="gripper_finger2_finger_tip_link" />
        <axis xyz="0 1 0" />
        <origin rpy="0.0 0.0 0.0" xyz="0.0394969463769  0.0 0.0382752038125  " />
        <limit effort="0.1" lower="-3.14" upper="3.14" velocity="100.0" />
        <mimic joint="gripper_finger1_joint" multiplier="1.49462955" />
    </joint>
    <link name="gripper_finger1_finger_tip_link">
        <visual>
            <geometry>
                <mesh filename="package://dh_ag95_description/meshes/visual/distal_phalanx_Link.STL" scale="0.001 0.001 0.001" />
            </geometry>
            <material name="white">
                <color rgba="1.0 1.0 1.0 1.0" />
            </material>
        </visual>
        <collision>
            <geometry>
                <mesh filename="package://dh_ag95_description/meshes/visual/distal_phalanx_Link.STL" scale="0.001 0.001 0.001" />
            </geometry>
        </collision>
        <inertial>
            <mass value="0.0124305" />
            <origin xyz="0.0 0.0 0.0" rpy="0 0 0" />
            <inertia ixx="2.84217e-06" ixy="-2.48048e-15" ixz="8.24539e-07" iyx="0.000000" iyy="3.03961e-06" iyz="2.16427e-13" izx="0.000000" izy="0.000000" izz="1.11815e-06" />
        </inertial>
    </link>
    <gazebo reference="gripper_finger1_finger_tip_link">
        <implicitSpringDamper>1</implicitSpringDamper>
        <mu1>100000</mu1>
        <mu2>100000</mu2>
        <kp>100000000.0</kp>
        <kd>1.0</kd>
    </gazebo>
    <link name="gripper_finger2_finger_tip_link">
        <visual>
            <geometry>
                <mesh filename="package://dh_ag95_description/meshes/visual/distal_phalanx_Link.STL" scale="0.001 0.001 0.001" />
            </geometry>
            <material name="white">
                <color rgba="1.0 1.0 1.0 1.0" />
            </material>
        </visual>
        <collision>
            <geometry>
                <mesh filename="package://dh_ag95_description/meshes/visual/distal_phalanx_Link.STL" scale="0.001 0.001 0.001" />
            </geometry>
        </collision>
        <inertial>
            <mass value="0.0124305" />
            <origin xyz="0.0 0.0 0.0" rpy="0 0 0" />
            <inertia ixx="2.84217e-06" ixy="-2.48048e-15" ixz="8.24539e-07" iyx="0.000000" iyy="3.03961e-06" iyz="2.16427e-13" izx="0.000000" izy="0.000000" izz="1.11815e-06" />
        </inertial>
    </link>
    <gazebo reference="gripper_finger2_finger_tip_link">
        <implicitSpringDamper>1</implicitSpringDamper>
        <mu1>100000</mu1>
        <mu2>100000</mu2>
        <kp>100000000.0</kp>
        <kd>1.0</kd>
    </gazebo>
    <transmission name="gripper_finger1_trans">
        <type>transmission_interface/SimpleTransmission</type>
        <joint name="gripper_finger1_joint">
            <hardwareInterface>hardware_interface/PositionJointInterface</hardwareInterface>
        </joint>
        <actuator name="gripper_finger1_motor">
            <mechanicalReduction>1</mechanicalReduction>
            <hardwareInterface>hardware_interface/PositionJointInterface</hardwareInterface>
        </actuator>
    </transmission>
    <gazebo>
        <!-- loading plugin: mimic joints works in gazebo now -->
        <plugin filename="libroboticsgroup_upatras_gazebo_mimic_joint_plugin.so" name="mimic_dh_robotics_ag95_1">
            <joint>gripper_finger1_joint</joint>
            <mimicJoint>gripper_finger2_joint</mimicJoint>
            <multiplier>1.0</multiplier>
            <offset>0.0</offset>
        </plugin>
        <plugin filename="libroboticsgroup_upatras_gazebo_mimic_joint_plugin.so" name="mimic_dh_robotics_ag95_2">
            <joint>gripper_finger1_joint</joint>
            <mimicJoint>gripper_finger2_inner_knuckle_joint</mimicJoint>
            <multiplier>1.49462955</multiplier>
            <offset>0.0</offset>
        </plugin>
        <plugin filename="libroboticsgroup_upatras_gazebo_mimic_joint_plugin.so" name="mimic_dh_robotics_ag95_3">
            <joint>gripper_finger1_joint</joint>
            <mimicJoint>gripper_finger1_inner_knuckle_joint</mimicJoint>
            <multiplier>1.49462955</multiplier>
            <offset>0.0</offset>
        </plugin>
        <plugin filename="libroboticsgroup_upatras_gazebo_mimic_joint_plugin.so" name="mimic_dh_robotics_ag95_4">
            <joint>gripper_finger1_joint</joint>
            <mimicJoint>gripper_finger1_finger_tip_joint</mimicJoint>
            <multiplier>1.49462955</multiplier>
            <offset>0.0</offset>
        </plugin>
        <plugin filename="libroboticsgroup_upatras_gazebo_mimic_joint_plugin.so" name="mimic_dh_robotics_ag95_5">
            <joint>gripper_finger1_joint</joint>
            <mimicJoint>gripper_finger2_finger_tip_joint</mimicJoint>
            <multiplier>1.49462955</multiplier>
            <offset>0.0</offset>
        </plugin>
        <plugin filename="libroboticsgroup_upatras_gazebo_mimic_joint_plugin.so" name="mimic_dh_robotics_ag95_6">
            <joint>gripper_finger1_joint</joint>
            <mimicJoint>gripper_finger1_finger_joint</mimicJoint>
            <multiplier>0.4563942</multiplier>
            <offset>0.0</offset>
        </plugin>
        <plugin filename="libroboticsgroup_upatras_gazebo_mimic_joint_plugin.so" name="mimic_dh_robotics_ag95_7">
            <joint>gripper_finger1_joint</joint>
            <mimicJoint>gripper_finger2_finger_joint</mimicJoint>
            <multiplier>0.4563942</multiplier>
            <offset>0.0</offset>
        </plugin>
    </gazebo>
    <transmission name="trans_joint1">
        <type>transmission_interface/SimpleTransmission</type>
        <joint name="joint1">
            <hardwareInterface>hardware_interface/PositionJointInterface</hardwareInterface>
        </joint>
        <actuator name="joint1_motor">
            <hardwareInterface>hardware_interface/PositionJointInterface</hardwareInterface>
            <mechanicalReduction>1</mechanicalReduction>
        </actuator>
    </transmission>
    <transmission name="trans_joint2">
        <type>transmission_interface/SimpleTransmission</type>
        <joint name="joint2">
            <hardwareInterface>hardware_interface/PositionJointInterface</hardwareInterface>
        </joint>
        <actuator name="joint2_motor">
            <hardwareInterface>hardware_interface/PositionJointInterface</hardwareInterface>
            <mechanicalReduction>1</mechanicalReduction>
        </actuator>
    </transmission>
    <transmission name="trans_joint3">
        <type>transmission_interface/SimpleTransmission</type>
        <joint name="joint3">
            <hardwareInterface>hardware_interface/PositionJointInterface</hardwareInterface>
        </joint>
        <actuator name="joint3_motor">
            <hardwareInterface>hardware_interface/PositionJointInterface</hardwareInterface>
            <mechanicalReduction>1</mechanicalReduction>
        </actuator>
    </transmission>
    <transmission name="trans_joint4">
        <type>transmission_interface/SimpleTransmission</type>
        <joint name="joint4">
            <hardwareInterface>hardware_interface/PositionJointInterface</hardwareInterface>
        </joint>
        <actuator name="joint4_motor">
            <hardwareInterface>hardware_interface/PositionJointInterface</hardwareInterface>
            <mechanicalReduction>1</mechanicalReduction>
        </actuator>
    </transmission>
    <transmission name="trans_joint5">
        <type>transmission_interface/SimpleTransmission</type>
        <joint name="joint5">
            <hardwareInterface>hardware_interface/PositionJointInterface</hardwareInterface>
        </joint>
        <actuator name="joint5_motor">
            <hardwareInterface>hardware_interface/PositionJointInterface</hardwareInterface>
            <mechanicalReduction>1</mechanicalReduction>
        </actuator>
    </transmission>
    <transmission name="trans_joint6">
        <type>transmission_interface/SimpleTransmission</type>
        <joint name="joint6">
            <hardwareInterface>hardware_interface/PositionJointInterface</hardwareInterface>
        </joint>
        <actuator name="joint6_motor">
            <hardwareInterface>hardware_interface/PositionJointInterface</hardwareInterface>
            <mechanicalReduction>1</mechanicalReduction>
        </actuator>
    </transmission>
    <transmission name="trans_joint7">
        <type>transmission_interface/SimpleTransmission</type>
        <joint name="joint7">
            <hardwareInterface>hardware_interface/PositionJointInterface</hardwareInterface>
        </joint>
        <actuator name="joint7_motor">
            <hardwareInterface>hardware_interface/PositionJointInterface</hardwareInterface>
            <mechanicalReduction>1</mechanicalReduction>
        </actuator>
    </transmission>
    <transmission name="trans_gripper_finger2_joint">
        <type>transmission_interface/SimpleTransmission</type>
        <joint name="gripper_finger2_joint">
            <hardwareInterface>hardware_interface/EffortJointInterface</hardwareInterface>
        </joint>
        <actuator name="gripper_finger2_joint_motor">
            <hardwareInterface>hardware_interface/EffortJointInterface</hardwareInterface>
            <mechanicalReduction>1</mechanicalReduction>
        </actuator>
    </transmission>
    <transmission name="trans_gripper_finger1_finger_joint">
        <type>transmission_interface/SimpleTransmission</type>
        <joint name="gripper_finger1_finger_joint">
            <hardwareInterface>hardware_interface/EffortJointInterface</hardwareInterface>
        </joint>
        <actuator name="gripper_finger1_finger_joint_motor">
            <hardwareInterface>hardware_interface/EffortJointInterface</hardwareInterface>
            <mechanicalReduction>1</mechanicalReduction>
        </actuator>
    </transmission>
    <transmission name="trans_gripper_finger2_finger_joint">
        <type>transmission_interface/SimpleTransmission</type>
        <joint name="gripper_finger2_finger_joint">
            <hardwareInterface>hardware_interface/EffortJointInterface</hardwareInterface>
        </joint>
        <actuator name="gripper_finger2_finger_joint_motor">
            <hardwareInterface>hardware_interface/EffortJointInterface</hardwareInterface>
            <mechanicalReduction>1</mechanicalReduction>
        </actuator>
    </transmission>
    <transmission name="trans_gripper_finger1_inner_knuckle_joint">
        <type>transmission_interface/SimpleTransmission</type>
        <joint name="gripper_finger1_inner_knuckle_joint">
            <hardwareInterface>hardware_interface/EffortJointInterface</hardwareInterface>
        </joint>
        <actuator name="gripper_finger1_inner_knuckle_joint_motor">
            <hardwareInterface>hardware_interface/EffortJointInterface</hardwareInterface>
            <mechanicalReduction>1</mechanicalReduction>
        </actuator>
    </transmission>
    <transmission name="trans_gripper_finger2_inner_knuckle_joint">
        <type>transmission_interface/SimpleTransmission</type>
        <joint name="gripper_finger2_inner_knuckle_joint">
            <hardwareInterface>hardware_interface/EffortJointInterface</hardwareInterface>
        </joint>
        <actuator name="gripper_finger2_inner_knuckle_joint_motor">
            <hardwareInterface>hardware_interface/EffortJointInterface</hardwareInterface>
            <mechanicalReduction>1</mechanicalReduction>
        </actuator>
    </transmission>
    <transmission name="trans_gripper_finger1_finger_tip_joint">
        <type>transmission_interface/SimpleTransmission</type>
        <joint name="gripper_finger1_finger_tip_joint">
            <hardwareInterface>hardware_interface/EffortJointInterface</hardwareInterface>
        </joint>
        <actuator name="gripper_finger1_finger_tip_joint_motor">
            <hardwareInterface>hardware_interface/EffortJointInterface</hardwareInterface>
            <mechanicalReduction>1</mechanicalReduction>
        </actuator>
    </transmission>
    <transmission name="trans_gripper_finger2_finger_tip_joint">
        <type>transmission_interface/SimpleTransmission</type>
        <joint name="gripper_finger2_finger_tip_joint">
            <hardwareInterface>hardware_interface/EffortJointInterface</hardwareInterface>
        </joint>
        <actuator name="gripper_finger2_finger_tip_joint_motor">
            <hardwareInterface>hardware_interface/EffortJointInterface</hardwareInterface>
            <mechanicalReduction>1</mechanicalReduction>
        </actuator>
    </transmission>
</robot>

